<?xml version='1.0'?>

<robot name="mobile_robot" xmlns:xacro="http://www.ros.org/wiki/xacro">

  <link name="robot_footprint"></link>
  <link name="base_link"></link>
  <xacro:include filename="$(find mobile_robot)/urdf/mobile_robot.gazebo" />

  <joint name="robot_base__joint" type="fixed">
    <origin xyz="0 0 0" rpy="0 0 0" />
    <parent link="robot_footprint"/>
    <child link="base_link" />
  </joint>
  <joint name="robot_footprint_joint" type="fixed">
    <origin xyz="0 0 0" rpy="0 0 0" />
    <parent link="base_link"/>
    <child link="chassis" />
  </joint>
  <link name='chassis'>
    <pose>0 0 0.1 0 0 0</pose>

    <inertial>
      <mass value="15.0"/>
      <origin xyz="0.0 0 0" rpy=" 0 0 0"/>
      <inertia
          ixx="0.1" ixy="0" ixz="0"
          iyy="0.1" iyz="0"
          izz="0.1"
      />
    </inertial>

  <collision name='collision'>
  <origin xyz="0 0 0" rpy=" 0 0 0"/> 
  <geometry>
    <cylinder length="0.1" radius="0.6"/>
  </geometry>
  </collision>

  <visual name='chassis_visual'>
    <origin xyz="0 0 0" rpy=" 0 0 0"/>
    <geometry>
      <cylinder length="0.1" radius="0.3"/>
    </geometry>
  </visual>


    <collision name='back_caster_collision'>
      <origin xyz="-0.15 0 -0.05" rpy=" 0 0 0"/>
      <geometry>
        <sphere radius="0.0499"/>
      </geometry>
    </collision>

    <visual name='back_caster_visual'>
      <origin xyz="-0.15 0 -0.05" rpy=" 0 0 0"/>
      <geometry>
        <sphere radius="0.05"/>
      </geometry>
    </visual>

    <collision name='front_caster_collision'>
      <origin xyz="0.15 0 -0.05" rpy=" 0 0 0"/>
      <geometry>
        <sphere radius="0.0499"/>
      </geometry>
    </collision>

    <visual name='front_caster_visual'>
      <origin xyz="0.15 0 -0.05" rpy=" 0 0 0"/>
      <geometry>
        <sphere radius="0.05"/>
      </geometry>
    </visual>

  </link>


  <link name='right_wheel'>
    <inertial>
      <mass value="5.0"/>
      <origin xyz="0 0 0" rpy="0 1.5707 1.5707"/>
      <inertia
          ixx="0.1" ixy="0" ixz="0"
          iyy="0.1" iyz="0"
          izz="0.1"
      />
    </inertial>

    <collision name='right_wheel_collision'>
      <origin xyz="0 0 0" rpy="0 1.5707 1.5707"/>
      <geometry>
        <cylinder length=".05" radius="0.1"/>
      </geometry>
    </collision>

    <visual name='right_wheel_visual'>
      <origin xyz="0 0 0" rpy="0 1.5707 1.5707"/>
      <geometry>
        <cylinder length=".05" radius="0.1"/>
      </geometry>
    </visual>
  </link>

  <joint type="continuous" name="right_wheel_hinge">
    <origin xyz="0 -0.15 0" rpy="0 0 0"/>
    <child link="right_wheel"/>
    <parent link="chassis"/>
    <axis xyz="0 1 0" rpy="0 0 0"/>
    <limit effort="10000" velocity="1000"/>
    <dynamics damping="1.0" friction="1.0"/>
  </joint>

  <link name='left_wheel'>
    <inertial>
      <mass value="5.0"/>
      <origin xyz="0 0 0" rpy="0 1.5707 1.5707"/>
      <inertia
          ixx="0.1" ixy="0" ixz="0"
          iyy="0.1" iyz="0"
          izz="0.1"
      />
    </inertial>

    <collision name='left_wheel_collision'>
      <origin xyz="0 0 0" rpy="0 1.5707 1.5707"/>
      <geometry>
        <cylinder length=".05" radius="0.1"/>
      </geometry>
    </collision>

    <visual name='left_wheel_visual'>
      <origin xyz="0 0 0" rpy="0 1.5707 1.5707"/>
      <geometry>
        <cylinder length=".05" radius="0.1"/>
      </geometry>
    </visual>
  </link>

  <joint type="continuous" name="left_wheel_hinge">
    <origin xyz="0 0.15 0" rpy="0 0 0"/>
    <child link="left_wheel"/>
    <parent link="chassis"/>
    <axis xyz="0 1 0" rpy="0 0 0"/>
    <limit effort="10000" velocity="1000"/>
    <dynamics damping="1.0" friction="1.0"/>
  </joint>


  <link name='camera'>
    <inertial>
      <mass value=".1"/>
      <origin xyz="0 0 0" rpy="0 0 0"/>
      <inertia
          ixx="1e-6" ixy="0" ixz="0"
          iyy="1e-6" iyz="0"
          izz="1e-6"
      />
    </inertial>

    <collision name='camera_collision'>
      <origin xyz="0 0 0" rpy="0 0 0"/>
      <geometry>
        <box size=".05 .05 .05"/>
      </geometry>
    </collision>

    <visual name='camera_visual'>
      <origin xyz="0 0 0" rpy="0 0 0"/>
      <geometry>
        <box size=".05 .05 .05"/>
      </geometry>
    </visual>
  </link>

  <joint name="camera_joint" type="fixed">
    <origin xyz=".225 0 0" rpy="0 0 0"/>
    <child link="camera"/>
    <parent link="chassis"/>
    <axis xyz="0 1 0" rpy="0 0 0"/>
  </joint>


  <link name='hokuyo'>
    <inertial>
      <mass value="1e-5"/>
      <origin xyz="0 0 0" rpy="0 0 0"/>
      <inertia
          ixx="1e-6" ixy="0" ixz="0"
          iyy="1e-6" iyz="0"
          izz="1e-6"
      />
    </inertial>

    <collision name='hokuyo_collision'>
      <origin xyz="0 0 0" rpy="0 0 0"/>
      <geometry>
        <box size=".1 .1 .1"/>
      </geometry>
    </collision>

    <visual name='hokuyo_visual'>
      <origin xyz="0 0 0" rpy="0 0 0"/>
      <geometry>
        <mesh filename = "package://mobile_robot/meshes/hokuyo.dae"/>
      </geometry>
    </visual>
  </link>

  <joint name="hokuyo_joint" type="fixed">
    <origin xyz="0 0 0.08" rpy="0 0 0"/>
    <child link="hokuyo"/>
    <parent link="chassis"/>
    <axis xyz="0 1 0" rpy="0 0 0"/>
  </joint>
<link name='laser'>
</link>
 <joint name="laser_joint" type="fixed">
    <origin xyz="0 0 0" rpy="0 0 3.140"/>
    <child link="laser"/>
    <parent link="hokuyo"/>
    <axis xyz="0 1 0" rpy="0 0 0"/>
  </joint>
  
  <gazebo reference="chassis">
    <material>Gazebo/Blue</material>
  </gazebo>
  <gazebo reference="left_wheel">
    <material>Gazebo/Green</material>
  </gazebo>
  <gazebo reference="right_wheel">
    <material>Gazebo/Green</material>
  </gazebo>
  <gazebo reference="camera">
    <material>Gazebo/Red</material>
  </gazebo>

</robot>
